Workbook

Sheet SemScore
B1: 1-ICE-IT | O1: 2-ICE-IT
B2: 1 | C2: 2 | D2: 3 | E2: 4 | F2: 5 | G2: 6 | H2: 7 | I2: 8 | J2: 9 | K2: 10 | O2: 1 | P2: 2 | Q2: 3 | R2: 4 | S2: 5 | T2: 6 | U2: 7 | V2: 8 | W2: 9 | X2: 10
A3: 1 | B3: 1 | C3: 0.9119 | D3: 0.9552 | E3: 0.9119 | F3: 0.9074 | G3: 0.9368 | H3: 0.9119 | I3: 0.8857 | J3: 0.891 | K3: 0.9472 | N3: 1 | O3: 1 | P3: 0.9197 | Q3: 0.9731 | R3: 0.9687 | S3: 0.9703 | T3: 0.9241 | U3: 0.957 | V3: 0.979 | W3: 0.9394 | X3: 0.9768
A4: 2 | B4: 0.9119 | C4: 1 | D4: 0.9344 | E4: 1 | F4: 0.9957 | G4: 0.931 | H4: 1 | I4: 0.8159 | J4: 0.8173 | K4: 0.8924 | N4: 2 | O4: 0.9197 | P4: 1 | Q4: 0.9483 | R4: 0.9344 | S4: 0.9211 | T4: 0.9916 | U4: 0.9307 | V4: 0.9213 | W4: 0.9216 | X4: 0.9472
A5: 3 | B5: 0.9552 | C5: 0.9344 | D5: 1 | E5: 0.9344 | F5: 0.9322 | G5: 0.9458 | H5: 0.9344 | I5: 0.8937 | J5: 0.8963 | K5: 0.9336 | N5: 3 | O5: 0.9731 | P5: 0.9483 | Q5: 1 | R5: 0.9714 | S5: 0.9767 | T5: 0.9464 | U5: 0.9593 | V5: 0.9783 | W5: 0.9427 | X5: 0.9919
A6: 4 | B6: 0.9119 | C6: 1 | D6: 0.9344 | E6: 1 | F6: 0.9957 | G6: 0.931 | H6: 1 | I6: 0.8159 | J6: 0.8173 | K6: 0.8924 | N6: 4 | O6: 0.9687 | P6: 0.9344 | Q6: 0.9714 | R6: 1 | S6: 0.9831 | T6: 0.9415 | U6: 0.9836 | V6: 0.9686 | W6: 0.9684 | X6: 0.9752
A7: 5 | B7: 0.9074 | C7: 0.9957 | D7: 0.9322 | E7: 0.9957 | F7: 1 | G7: 0.9268 | H7: 0.9957 | I7: 0.8066 | J7: 0.8079 | K7: 0.8932 | N7: 5 | O7: 0.9703 | P7: 0.9211 | Q7: 0.9767 | R7: 0.9831 | S7: 1 | T7: 0.9239 | U7: 0.9761 | V7: 0.9824 | W7: 0.9571 | X7: 0.9826
A8: 6 | B8: 0.9368 | C8: 0.931 | D8: 0.9458 | E8: 0.931 | F8: 0.9268 | G8: 1 | H8: 0.931 | I8: 0.9069 | J8: 0.9077 | K8: 0.9361 | N8: 6 | O8: 0.9241 | P8: 0.9916 | Q8: 0.9464 | R8: 0.9415 | S8: 0.9239 | T8: 1 | U8: 0.9361 | V8: 0.923 | W8: 0.9248 | X8: 0.9483
A9: 7 | B9: 0.9119 | C9: 1 | D9: 0.9344 | E9: 1 | F9: 0.9957 | G9: 0.931 | H9: 1 | I9: 0.8159 | J9: 0.8173 | K9: 0.8924 | N9: 7 | O9: 0.957 | P9: 0.9307 | Q9: 0.9593 | R9: 0.9836 | S9: 0.9761 | T9: 0.9361 | U9: 1 | V9: 0.9605 | W9: 0.9654 | X9: 0.9649
A10: 8 | B10: 0.8857 | C10: 0.8159 | D10: 0.8937 | E10: 0.8159 | F10: 0.8066 | G10: 0.9069 | H10: 0.8159 | I10: 1 | J10: 0.9996 | K10: 0.8493 | N10: 8 | O10: 0.979 | P10: 0.9213 | Q10: 0.9783 | R10: 0.9686 | S10: 0.9824 | T10: 0.923 | U10: 0.9605 | V10: 1 | W10: 0.9439 | X10: 0.9835
A11: 9 | B11: 0.891 | C11: 0.8173 | D11: 0.8963 | E11: 0.8173 | F11: 0.8079 | G11: 0.9077 | H11: 0.8173 | I11: 0.9996 | J11: 1 | K11: 0.8548 | N11: 9 | O11: 0.9394 | P11: 0.9216 | Q11: 0.9427 | R11: 0.9684 | S11: 0.9571 | T11: 0.9248 | U11: 0.9654 | V11: 0.9439 | W11: 1 | X11: 0.9459
A12: 10 | B12: 0.9472 | C12: 0.8924 | D12: 0.9336 | E12: 0.8924 | F12: 0.8932 | G12: 0.9361 | H12: 0.8924 | I12: 0.8493 | J12: 0.8548 | K12: 1 | N12: 10 | O12: 0.9768 | P12: 0.9472 | Q12: 0.9919 | R12: 0.9752 | S12: 0.9826 | T12: 0.9483 | U12: 0.9649 | V12: 0.9835 | W12: 0.9459 | X12: 1
B14: 3-ICE-IT | O14: 4-ICE-IT
B15: 1 | C15: 2 | D15: 3 | E15: 4 | F15: 5 | G15: 6 | H15: 7 | I15: 8 | J15: 9 | K15: 10 | O15: 1 | P15: 2 | Q15: 3 | R15: 4 | S15: 5 | T15: 6 | U15: 7 | V15: 8 | W15: 9 | X15: 10
A16: 1 | B16: 1 | C16: 0.9874 | D16: 0.9928 | E16: 0.9815 | F16: 0.9774 | G16: 0.9791 | H16: 0.9689 | I16: 0.9891 | J16: 0.9855 | K16: 0.9698 | N16: 1 | O16: 1 | P16: 0.9869 | Q16: 0.9866 | R16: 0.9337 | S16: 0.9864 | T16: 0.9871 | U16: 0.9719 | V16: 0.9672 | W16: 0.959 | X16: 0.9594
A17: 2 | B17: 0.9874 | C17: 1 | D17: 0.9844 | E17: 0.9836 | F17: 0.965 | G17: 0.9738 | H17: 0.9745 | I17: 0.9855 | J17: 0.9816 | K17: 0.9562 | N17: 2 | O17: 0.9869 | P17: 1 | Q17: 0.9965 | R17: 0.9343 | S17: 0.9661 | T17: 0.9768 | U17: 0.9582 | V17: 0.9652 | W17: 0.956 | X17: 0.9422
A18: 3 | B18: 0.9928 | C18: 0.9844 | D18: 1 | E18: 0.9833 | F18: 0.9893 | G18: 0.9866 | H18: 0.9791 | I18: 0.9914 | J18: 0.9836 | K18: 0.9805 | N18: 3 | O18: 0.9866 | P18: 0.9965 | Q18: 1 | R18: 0.937 | S18: 0.9684 | T18: 0.9766 | U18: 0.9526 | V18: 0.9635 | W18: 0.9526 | X18: 0.9397
A19: 4 | B19: 0.9815 | C19: 0.9836 | D19: 0.9833 | E19: 1 | F19: 0.9692 | G19: 0.9703 | H19: 0.9849 | I19: 0.9786 | J19: 0.9829 | K19: 0.9665 | N19: 4 | O19: 0.9337 | P19: 0.9343 | Q19: 0.937 | R19: 1 | S19: 0.9126 | T19: 0.9158 | U19: 0.9109 | V19: 0.9251 | W19: 0.8817 | X19: 0.8961
A20: 5 | B20: 0.9774 | C20: 0.965 | D20: 0.9893 | E20: 0.9692 | F20: 1 | G20: 0.9838 | H20: 0.9719 | I20: 0.9833 | J20: 0.9742 | K20: 0.9863 | N20: 5 | O20: 0.9864 | P20: 0.9661 | Q20: 0.9684 | R20: 0.9126 | S20: 1 | T20: 0.9936 | U20: 0.9747 | V20: 0.9594 | W20: 0.9631 | X20: 0.9703
A21: 6 | B21: 0.9791 | C21: 0.9738 | D21: 0.9866 | E21: 0.9703 | F21: 0.9838 | G21: 1 | H21: 0.9721 | I21: 0.9868 | J21: 0.9703 | K21: 0.9773 | N21: 6 | O21: 0.9871 | P21: 0.9768 | Q21: 0.9766 | R21: 0.9158 | S21: 0.9936 | T21: 1 | U21: 0.9825 | V21: 0.9706 | W21: 0.9765 | X21: 0.9698
A22: 7 | B22: 0.9689 | C22: 0.9745 | D22: 0.9791 | E22: 0.9849 | F22: 0.9719 | G22: 0.9721 | H22: 1 | I22: 0.9749 | J22: 0.9704 | K22: 0.9617 | N22: 7 | O22: 0.9719 | P22: 0.9582 | Q22: 0.9526 | R22: 0.9109 | S22: 0.9747 | T22: 0.9825 | U22: 1 | V22: 0.9808 | W22: 0.9722 | X22: 0.9743
A23: 8 | B23: 0.9891 | C23: 0.9855 | D23: 0.9914 | E23: 0.9786 | F23: 0.9833 | G23: 0.9868 | H23: 0.9749 | I23: 1 | J23: 0.9756 | K23: 0.9735 | N23: 8 | O23: 0.9672 | P23: 0.9652 | Q23: 0.9635 | R23: 0.9251 | S23: 0.9594 | T23: 0.9706 | U23: 0.9808 | V23: 1 | W23: 0.9676 | X23: 0.9639
A24: 9 | B24: 0.9855 | C24: 0.9816 | D24: 0.9836 | E24: 0.9829 | F24: 0.9742 | G24: 0.9703 | H24: 0.9704 | I24: 0.9756 | J24: 1 | K24: 0.9737 | N24: 9 | O24: 0.959 | P24: 0.956 | Q24: 0.9526 | R24: 0.8817 | S24: 0.9631 | T24: 0.9765 | U24: 0.9722 | V24: 0.9676 | W24: 1 | X24: 0.9601
A25: 10 | B25: 0.9698 | C25: 0.9562 | D25: 0.9805 | E25: 0.9665 | F25: 0.9863 | G25: 0.9773 | H25: 0.9617 | I25: 0.9735 | J25: 0.9737 | K25: 1 | N25: 10 | O25: 0.9594 | P25: 0.9422 | Q25: 0.9397 | R25: 0.8961 | S25: 0.9703 | T25: 0.9698 | U25: 0.9743 | V25: 0.9639 | W25: 0.9601 | X25: 1
B27: 1-IRN-IT | O27: 2-IRN-IT
B28: 1 | C28: 2 | D28: 3 | E28: 4 | F28: 5 | G28: 6 | H28: 7 | I28: 8 | J28: 9 | K28: 10 | O28: 1 | P28: 2 | Q28: 3 | R28: 4 | S28: 5 | T28: 6 | U28: 7 | V28: 8 | W28: 9 | X28: 10
A29: 1 | B29: 1 | C29: 0.9935 | D29: 0.9877 | E29: 0.9929 | F29: 0.9903 | G29: 0.9894 | H29: 0.9765 | I29: 0.9735 | J29: 0.9738 | K29: 0.9775 | N29: 1 | O29: 1 | P29: 0.9948 | Q29: 0.9753 | R29: 0.985 | S29: 0.9796 | T29: 0.9785 | U29: 0.9885 | V29: 0.9865 | W29: 0.9832 | X29: 0.9952
A30: 2 | B30: 0.9935 | C30: 1 | D30: 0.9823 | E30: 0.9994 | F30: 0.9886 | G30: 0.9824 | H30: 0.9758 | I30: 0.9771 | J30: 0.9792 | K30: 0.9873 | N30: 2 | O30: 0.9948 | P30: 1 | Q30: 0.9758 | R30: 0.9858 | S30: 0.9791 | T30: 0.9826 | U30: 0.9896 | V30: 0.9888 | W30: 0.9833 | X30: 0.9978
A31: 3 | B31: 0.9877 | C31: 0.9823 | D31: 1 | E31: 0.9821 | F31: 0.9829 | G31: 0.9871 | H31: 0.9818 | I31: 0.9753 | J31: 0.9746 | K31: 0.97 | N31: 3 | O31: 0.9753 | P31: 0.9758 | Q31: 1 | R31: 0.9852 | S31: 0.9776 | T31: 0.9741 | U31: 0.981 | V31: 0.9815 | W31: 0.9719 | X31: 0.9748
A32: 4 | B32: 0.9929 | C32: 0.9994 | D32: 0.9821 | E32: 1 | F32: 0.9873 | G32: 0.9811 | H32: 0.9764 | I32: 0.9772 | J32: 0.9794 | K32: 0.9882 | N32: 4 | O32: 0.985 | P32: 0.9858 | Q32: 0.9852 | R32: 1 | S32: 0.9828 | T32: 0.9823 | U32: 0.9899 | V32: 0.9916 | W32: 0.9829 | X32: 0.9857
A33: 5 | B33: 0.9903 | C33: 0.9886 | D33: 0.9829 | E33: 0.9873 | F33: 1 | G33: 0.985 | H33: 0.9757 | I33: 0.9734 | J33: 0.9727 | K33: 0.9699 | N33: 5 | O33: 0.9796 | P33: 0.9791 | Q33: 0.9776 | R33: 0.9828 | S33: 1 | T33: 0.9758 | U33: 0.9908 | V33: 0.9786 | W33: 0.9737 | X33: 0.9771
A34: 6 | B34: 0.9894 | C34: 0.9824 | D34: 0.9871 | E34: 0.9811 | F34: 0.985 | G34: 1 | H34: 0.981 | I34: 0.9697 | J34: 0.968 | K34: 0.9666 | N34: 6 | O34: 0.9785 | P34: 0.9826 | Q34: 0.9741 | R34: 0.9823 | S34: 0.9758 | T34: 1 | U34: 0.9812 | V34: 0.9857 | W34: 0.9794 | X34: 0.9827
A35: 7 | B35: 0.9765 | C35: 0.9758 | D35: 0.9818 | E35: 0.9764 | F35: 0.9757 | G35: 0.981 | H35: 1 | I35: 0.9705 | J35: 0.9715 | K35: 0.9718 | N35: 7 | O35: 0.9885 | P35: 0.9896 | Q35: 0.981 | R35: 0.9899 | S35: 0.9908 | T35: 0.9812 | U35: 1 | V35: 0.9862 | W35: 0.9805 | X35: 0.9897
A36: 8 | B36: 0.9735 | C36: 0.9771 | D36: 0.9753 | E36: 0.9772 | F36: 0.9734 | G36: 0.9697 | H36: 0.9705 | I36: 1 | J36: 0.9987 | K36: 0.9782 | N36: 8 | O36: 0.9865 | P36: 0.9888 | Q36: 0.9815 | R36: 0.9916 | S36: 0.9786 | T36: 0.9857 | U36: 0.9862 | V36: 1 | W36: 0.9891 | X36: 0.989
A37: 9 | B37: 0.9738 | C37: 0.9792 | D37: 0.9746 | E37: 0.9794 | F37: 0.9727 | G37: 0.968 | H37: 0.9715 | I37: 0.9987 | J37: 1 | K37: 0.9815 | N37: 9 | O37: 0.9832 | P37: 0.9833 | Q37: 0.9719 | R37: 0.9829 | S37: 0.9737 | T37: 0.9794 | U37: 0.9805 | V37: 0.9891 | W37: 1 | X37: 0.9824
A38: 10 | B38: 0.9775 | C38: 0.9873 | D38: 0.97 | E38: 0.9882 | F38: 0.9699 | G38: 0.9666 | H38: 0.9718 | I38: 0.9782 | J38: 0.9815 | K38: 1 | N38: 10 | O38: 0.9952 | P38: 0.9978 | Q38: 0.9748 | R38: 0.9857 | S38: 0.9771 | T38: 0.9827 | U38: 0.9897 | V38: 0.989 | W38: 0.9824 | X38: 1
B40: 3-IRN-IT | O40: 4-IRN-IT
B41: 1 | C41: 2 | D41: 3 | E41: 4 | F41: 5 | G41: 6 | H41: 7 | I41: 8 | J41: 9 | K41: 10 | O41: 1 | P41: 2 | Q41: 3 | R41: 4 | S41: 5 | T41: 6 | U41: 7 | V41: 8 | W41: 9 | X41: 10
A42: 1 | B42: 1 | C42: 0.992 | D42: 0.9834 | E42: 0.992 | F42: 0.9967 | G42: 0.9734 | H42: 0.995 | I42: 0.9746 | J42: 0.9924 | K42: 0.9763 | N42: 1 | O42: 1 | P42: 0.9975 | Q42: 1 | R42: 0.9983 | S42: 0.9979 | T42: 0.9908 | U42: 0.9853 | V42: 0.9856 | W42: 0.9809 | X42: 0.9791
A43: 2 | B43: 0.992 | C43: 1 | D43: 0.9817 | E43: 1 | F43: 0.9879 | G43: 0.9785 | H43: 0.9978 | I43: 0.9765 | J43: 0.9928 | K43: 0.9762 | N43: 2 | O43: 0.9975 | P43: 1 | Q43: 0.9975 | R43: 0.9986 | S43: 0.9972 | T43: 0.9891 | U43: 0.9828 | V43: 0.9841 | W43: 0.9809 | X43: 0.9788
...

Sheet Graphs
B3: 1-ICE-IT | C3: {=SemScore!C3:K3} -> 0.9119 | D3: 0.9552 | E3: 0.9119 | F3: 0.9074 | G3: 0.9368 | H3: 0.9119 | I3: 0.8857 | J3: 0.891 | K3: 0.9472 | L3: {=SemScore!D4:K4} -> 0.9344 | M3: 1 | N3: 0.9957 | O3: 0.931 | P3: 1 | Q3: 0.8159 | R3: 0.8173 | S3: 0.8924 | T3: {=SemScore!E5:K5} -> 0.9344 | U3: 0.9322 | V3: 0.9458 | W3: 0.9344 | X3: 0.8937 | Y3: 0.8963 | Z3: 0.9336 | AA3: {=SemScore!F6:K6} -> 0.9957 | AB3: 0.931 | AC3: 1 | AD3: 0.8159 | AE3: 0.8173 | AF3: 0.8924 | AG3: {=SemScore!G7:K7} -> 0.9268 | AH3: 0.9957 | AI3: 0.8066 | AJ3: 0.8079 | AK3: 0.8932 | AL3: {=SemScore!H8:K8} -> 0.931 | AM3: 0.9069 | AN3: 0.9077 | AO3: 0.9361 | AP3: {=SemScore!I9:K9} -> 0.8159 | AQ3: 0.8173 | AR3: 0.8924 | AS3: {=SemScore!J10:K10} -> 0.9996 | AT3: 0.8493 | AU3: =SemScore!K11 -> 0.8548
B4: 2-ICE-IT | C4: {=SemScore!P3:X3} -> 0.9197 | D4: 0.9731 | E4: 0.9687 | F4: 0.9703 | G4: 0.9241 | H4: 0.957 | I4: 0.979 | J4: 0.9394 | K4: 0.9768 | L4: {=SemScore!Q4:X4} -> 0.9483 | M4: 0.9344 | N4: 0.9211 | O4: 0.9916 | P4: 0.9307 | Q4: 0.9213 | R4: 0.9216 | S4: 0.9472 | T4: {=SemScore!R5:X5} -> 0.9714 | U4: 0.9767 | V4: 0.9464 | W4: 0.9593 | X4: 0.9783 | Y4: 0.9427 | Z4: 0.9919 | AA4: {=SemScore!S6:X6} -> 0.9831 | AB4: 0.9415 | AC4: 0.9836 | AD4: 0.9686 | AE4: 0.9684 | AF4: 0.9752 | AG4: {=SemScore!T7:X7} -> 0.9239 | AH4: 0.9761 | AI4: 0.9824 | AJ4: 0.9571 | AK4: 0.9826 | AL4: {=SemScore!U8:X8} -> 0.9361 | AM4: 0.923 | AN4: 0.9248 | AO4: 0.9483 | AP4: {=SemScore!V9:X9} -> 0.9605 | AQ4: 0.9654 | AR4: 0.9649 | AS4: {=SemScore!W10:X10} -> 0.9439 | AT4: 0.9835 | AU4: =SemScore!X11 -> 0.9459
B5: 3-ICE-IT | C5: {=SemScore!C16:K16} -> 0.9874 | D5: 0.9928 | E5: 0.9815 | F5: 0.9774 | G5: 0.9791 | H5: 0.9689 | I5: 0.9891 | J5: 0.9855 | K5: 0.9698 | L5: {=SemScore!D17:K17} -> 0.9844 | M5: 0.9836 | N5: 0.965 | O5: 0.9738 | P5: 0.9745 | Q5: 0.9855 | R5: 0.9816 | S5: 0.9562 | T5: {=SemScore!E18:K18} -> 0.9833 | U5: 0.9893 | V5: 0.9866 | W5: 0.9791 | X5: 0.9914 | Y5: 0.9836 | Z5: 0.9805 | AA5: {=SemScore!F19:K19} -> 0.9692 | AB5: 0.9703 | AC5: 0.9849 | AD5: 0.9786 | AE5: 0.9829 | AF5: 0.9665 | AG5: {=SemScore!G20:K20} -> 0.9838 | AH5: 0.9719 | AI5: 0.9833 | AJ5: 0.9742 | AK5: 0.9863 | AL5: {=SemScore!H21:K21} -> 0.9721 | AM5: 0.9868 | AN5: 0.9703 | AO5: 0.9773 | AP5: {=SemScore!I22:K22} -> 0.9749 | AQ5: 0.9704 | AR5: 0.9617 | AS5: {=SemScore!J23:K23} -> 0.9756 | AT5: 0.9735 | AU5: =SemScore!K24 -> 0.9737
B6: 4-ICE-IT | C6: {=SemScore!P16:X16} -> 0.9869 | D6: 0.9866 | E6: 0.9337 | F6: 0.9864 | G6: 0.9871 | H6: 0.9719 | I6: 0.9672 | J6: 0.959 | K6: 0.9594 | L6: {=SemScore!Q17:X17} -> 0.9965 | M6: 0.9343 | N6: 0.9661 | O6: 0.9768 | P6: 0.9582 | Q6: 0.9652 | R6: 0.956 | S6: 0.9422 | T6: {=SemScore!R18:X18} -> 0.937 | U6: 0.9684 | V6: 0.9766 | W6: 0.9526 | X6: 0.9635 | Y6: 0.9526 | Z6: 0.9397 | AA6: {=SemScore!S19:X19} -> 0.9126 | AB6: 0.9158 | AC6: 0.9109 | AD6: 0.9251 | AE6: 0.8817 | AF6: 0.8961 | AG6: {=SemScore!T20:X20} -> 0.9936 | AH6: 0.9747 | AI6: 0.9594 | AJ6: 0.9631 | AK6: 0.9703 | AL6: {=SemScore!U21:X21} -> 0.9825 | AM6: 0.9706 | AN6: 0.9765 | AO6: 0.9698 | AP6: {=SemScore!V22:X22} -> 0.9808 | AQ6: 0.9722 | AR6: 0.9743 | AS6: {=SemScore!W23:X23} -> 0.9676 | AT6: 0.9639 | AU6: =SemScore!X24 -> 0.9601
B7: 1-IRN-IT | C7: {=SemScore!C29:K29} -> 0.9935 | D7: 0.9877 | E7: 0.9929 | F7: 0.9903 | G7: 0.9894 | H7: 0.9765 | I7: 0.9735 | J7: 0.9738 | K7: 0.9775 | L7: {=SemScore!D30:K30} -> 0.9823 | M7: 0.9994 | N7: 0.9886 | O7: 0.9824 | P7: 0.9758 | Q7: 0.9771 | R7: 0.9792 | S7: 0.9873 | T7: {=SemScore!E31:K31} -> 0.9821 | U7: 0.9829 | V7: 0.9871 | W7: 0.9818 | X7: 0.9753 | Y7: 0.9746 | Z7: 0.97 | AA7: {=SemScore!F32:K32} -> 0.9873 | AB7: 0.9811 | AC7: 0.9764 | AD7: 0.9772 | AE7: 0.9794 | AF7: 0.9882 | AG7: {=SemScore!G33:K33} -> 0.985 | AH7: 0.9757 | AI7: 0.9734 | AJ7: 0.9727 | AK7: 0.9699 | AL7: {=SemScore!H34:K34} -> 0.981 | AM7: 0.9697 | AN7: 0.968 | AO7: 0.9666 | AP7: {=SemScore!I35:K35} -> 0.9705 | AQ7: 0.9715 | AR7: 0.9718 | AS7: {=SemScore!J36:K36} -> 0.9987 | AT7: 0.9782 | AU7: =SemScore!K37 -> 0.9815
B8: 2-IRN-IT | C8: {=SemScore!P29:X29} -> 0.9948 | D8: 0.9753 | E8: 0.985 | F8: 0.9796 | G8: 0.9785 | H8: 0.9885 | I8: 0.9865 | J8: 0.9832 | K8: 0.9952 | L8: {=SemScore!Q30:X30} -> 0.9758 | M8: 0.9858 | N8: 0.9791 | O8: 0.9826 | P8: 0.9896 | Q8: 0.9888 | R8: 0.9833 | S8: 0.9978 | T8: {=SemScore!R31:X31} -> 0.9852 | U8: 0.9776 | V8: 0.9741 | W8: 0.981 | X8: 0.9815 | Y8: 0.9719 | Z8: 0.9748 | AA8: {=SemScore!S32:X32} -> 0.9828 | AB8: 0.9823 | AC8: 0.9899 | AD8: 0.9916 | AE8: 0.9829 | AF8: 0.9857 | AG8: {=SemScore!T33:X33} -> 0.9758 | AH8: 0.9908 | AI8: 0.9786 | AJ8: 0.9737 | AK8: 0.9771 | AL8: {=SemScore!U34:X34} -> 0.9812 | AM8: 0.9857 | AN8: 0.9794 | AO8: 0.9827 | AP8: {=SemScore!V35:X35} -> 0.9862 | AQ8: 0.9805 | AR8: 0.9897 | AS8: {=SemScore!W36:X36} -> 0.9891 | AT8: 0.989 | AU8: =SemScore!X37 -> 0.9824
B9: 3-IRN-IT | C9: {=SemScore!C42:K42} -> 0.992 | D9: 0.9834 | E9: 0.992 | F9: 0.9967 | G9: 0.9734 | H9: 0.995 | I9: 0.9746 | J9: 0.9924 | K9: 0.9763 | L9: {=SemScore!D43:K43} -> 0.9817 | M9: 1 | N9: 0.9879 | O9: 0.9785 | P9: 0.9978 | Q9: 0.9765 | R9: 0.9928 | S9: 0.9762 | T9: {=SemScore!E44:K44} -> 0.9817 | U9: 0.9842 | V9: 0.9687 | W9: 0.9837 | X9: 0.9714 | Y9: 0.9833 | Z9: 0.9766 | AA9: {=SemScore!F45:K45} -> 0.9879 | AB9: 0.9785 | AC9: 0.9978 | AD9: 0.9765 | AE9: 0.9928 | AF9: 0.9762 | AG9: {=SemScore!G46:K46} -> 0.9733 | AH9: 0.9927 | AI9: 0.9753 | AJ9: 0.9928 | AK9: 0.9784 | AL9: {=SemScore!H47:K47} -> 0.9795 | AM9: 0.9662 | AN9: 0.9821 | AO9: 0.9642 | AP9: {=SemScore!I48:K48} -> 0.9788 | AQ9: 0.9955 | AR9: 0.9791 | AS9: {=SemScore!J49:K49} -> 0.9755 | AT9: 0.9979 | AU9: =SemScore!K50 -> 0.9772
B10: 4-IRN-IT | C10: {=SemScore!P42:X42} -> 0.9975 | D10: 1 | E10: 0.9983 | F10: 0.9979 | G10: 0.9908 | H10: 0.9853 | I10: 0.9856 | J10: 0.9809 | K10: 0.9791 | L10: {=SemScore!Q43:X43} -> 0.9975 | M10: 0.9986 | N10: 0.9972 | O10: 0.9891 | P10: 0.9828 | Q10: 0.9841 | R10: 0.9809 | S10: 0.9788 | T10: {=SemScore!R44:X44} -> 0.9983 | U10: 0.9979 | V10: 0.9908 | W10: 0.9853 | X10: 0.9856 | Y10: 0.9809 | Z10: 0.9791 | AA10: {=SemScore!S45:X45} -> 0.9965 | AB10: 0.9904 | AC10: 0.9849 | AD10: 0.987 | AE10: 0.9837 | AF10: 0.9817 | AG10: {=SemScore!T46:X46} -> 0.9899 | AH10: 0.9875 | AI10: 0.987 | AJ10: 0.9836 | AK10: 0.9797 | AL10: {=SemScore!U47:X47} -> 0.9895 | AM10: 0.9912 | AN10: 0.9863 | AO10: 0.9839 | AP10: {=SemScore!V48:X48} -> 0.9956 | AQ10: 0.9934 | AR10: 0.9839 | AS10: {=SemScore!W49:X49} -> 0.9966 | AT10: 0.9871 | AU10: =SemScore!X50 -> 0.9891
B11: 1-ASK-IT | C11: {=SemScore!C55:K55} -> 0.9588 | D11: 0.9703 | E11: 0.9532 | F11: 0.9731 | G11: 0.9518 | H11: 0.9497 | I11: 0.9497 | J11: 0.9587 | K11: 0.9727 | L11: {=SemScore!D56:K56} -> 0.9753 | M11: 0.9823 | N11: 0.9748 | O11: 0.9776 | P11: 0.9776 | Q11: 0.9776 | R11: 0.9809 | S11: 0.9745 | T11: {=SemScore!E57:K57} -> 0.9696 | U11: 0.9703 | V11: 0.9713 | W11: 0.9665 | X11: 0.9665 | Y11: 0.9755 | Z11: 0.9954 | AA11: {=SemScore!F58:K58} -> 0.9638 | AB11: 0.9905 | AC11: 0.9536 | AD11: 0.9536 | AE11: 0.993 | AF11: 0.9654 | AG11: {=SemScore!G59:K59} -> 0.9672 | AH11: 0.9695 | AI11: 0.9695 | AJ11: 0.972 | AK11: 0.973 | AL11: {=SemScore!H60:K60} -> 0.9655 | AM11: 0.9655 | AN11: 0.9952 | AO11: 0.97 | AP11: {=SemScore!I61:K61} -> 1 | AQ11: 0.972 | AR11: 0.9711 | AS11: {=SemScore!J62:K62} -> 0.972 | AT11: 0.9711 | AU11: =SemScore!K63 -> 0.9743
B12: 2-ASK-IT | C12: {=SemScore!P55:X55} -> 0.8686 | D12: 0.8469 | E12: 0.898 | F12: 0.8689 | G12: 0.853 | H12: 0.8738 | I12: 0.8512 | J12: 0.7599 | K12: 0.9336 | L12: {=SemScore!Q56:X56} -> 0.9736 | M12: 0.9056 | N12: 0.9442 | O12: 0.9371 | P12: 0.9231 | Q12: 0.9658 | R12: 0.8945 | S12: 0.8648 | T12: {=SemScore!R57:X57} -> 0.9099 | U12: 0.9472 | V12: 0.9371 | W12: 0.9201 | X12: 0.972 | Y12: 0.8992 | Z12: 0.8407 | AA12: {=SemScore!S58:X58} -> 0.8931 | AB12: 0.8833 | AC12: 0.8874 | AD12: 0.9015 | AE12: 0.794 | AF12: 0.9261 | AG12: {=SemScore!T59:X59} -> 0.9068 | AH12: 0.9562 | AI12: 0.9396 | AJ12: 0.8673 | AK12: 0.8453 | AL12: {=SemScore!U60:X60} -> 0.8798 | AM12: 0.9478 | AN12: 0.8841 | AO12: 0.8411 | AP12: {=SemScore!V61:X61} -> 0.8953 | AQ12: 0.8654 | AR12: 0.8545 | AS12: {=SemScore!W62:X62} -> 0.8922 | AT12: 0.8378 | AU12: =SemScore!X63 -> 0.7589
B13: 3-ASK-IT | C13: {=SemScore!C68:K68} -> 0.9697 | D13: 0.9829 | E13: 0.9816 | F13: 0.9886 | G13: 0.9616 | H13: 0.9793 | I13: 0.9781 | J13: 0.9765 | K13: 0.9702 | L13: {=SemScore!D69:K69} -> 0.9713 | M13: 0.9797 | N13: 0.962 | O13: 0.9751 | P13: 0.9833 | Q13: 0.9686 | R13: 0.9845 | S13: 0.9714 | T13: {=SemScore!E70:K70} -> 0.9787 | U13: 0.9782 | V13: 0.975 | W13: 0.9762 | X13: 0.9592 | Y13: 0.9733 | Z13: 0.9863 | AA13: {=SemScore!F71:K71} -> 0.9721 | AB13: 0.961 | AC13: 0.9802 | AD13: 0.9767 | AE13: 0.99 | AF13: 0.9735 | AG13: {=SemScore!G72:K72} -> 0.9671 | AH13: 0.9759 | AI13: 0.9694 | AJ13: 0.9606 | AK13: 0.9763 | AL13: {=SemScore!H73:K73} -> 0.9724 | AM13: 0.948 | AN13: 0.9589 | AO13: 0.9836 | AP13: {=SemScore!I74:K74} -> 0.9768 | AQ13: 0.9827 | AR13: 0.9708 | AS13: {=SemScore!J75:K75} -> 0.9795 | AT13: 0.9581 | AU13: =SemScore!K76 -> 0.9688
B14: 4-ASK-IT | C14: {=SemScore!P68:X68} -> 0.9854 | D14: 0.9717 | E14: 0.9814 | F14: 0.9801 | G14: 0.9764 | H14: 0.9765 | I14: 0.9981 | J14: 0.9729 | K14: 0.9723 | L14: {=SemScore!Q69:X69} -> 0.984 | M14: 0.9926 | N14: 0.9747 | O14: 0.9876 | P14: 0.9883 | Q14: 0.9873 | R14: 0.9848 | S14: 0.9822 | T14: {=SemScore!R70:X70} -> 0.9797 | U14: 0.9566 | V14: 0.9669 | W14: 0.9734 | X14: 0.9728 | Y14: 0.9871 | Z14: 0.9936 | AA14: {=SemScore!S71:X71} -> 0.9712 | AB14: 0.9779 | AC14: 0.9949 | AD14: 0.9842 | AE14: 0.9765 | AF14: 0.9785 | AG14: {=SemScore!T72:X72} -> 0.9677 | AH14: 0.9673 | AI14: 0.9837 | AJ14: 0.9478 | AK14: 0.9544 | AL14: {=SemScore!U73:X73} -> 0.9725 | AM14: 0.9769 | AN14: 0.9737 | AO14: 0.9635 | AP14: {=SemScore!V74:X74} -> 0.9786 | AQ14: 0.9702 | AR14: 0.9693 | AS14: {=SemScore!W75:X75} -> 0.972 | AT14: 0.9729 | AU14: =SemScore!X76 -> 0.9849
